Workbook
Name Siema2024: #REF!
Name Siema2025: 'Siema 2025'!$1:$1048576

Sheet Siema 2025
A1: 1 - Número de Registro | B1: 2 - Data do Incidente | C1: 3 - Município | D1: 4 - UF | E1: 5 - Origem | F1: 6 - Tipo de Evento | G1: 7 - Produtos ONU | H1: 8 - Qtd. Produtos ONU | I1: 9 - Unidade Produtos ONU | J1: 10 - Outros Produtos | K1: 11 - Qtd. Outros Produtos | L1: 12 - Unidade Outros Produtos | M1: 13 - Ocorrências/Ambientes Atingidos | N1: 14 - Inst. Atuando no Local | O1: 15 - Fontes de Informação | P1: 16 - Dia da Semana | Q1: 17 - Período | R1: 18 - Feriado | S1: 19 - Bacia Sedimentar | T1: 20 - Endereço da Ocorrência | U1: 21 - Origem do Acidente - Informações Complementares | V1: 22 - Tipo de evento - Informações Complementares | W1: 23 - Produto perigoso | X1: 24 - Produto não se aplica | Y1: 25 - Produto não especificado | Z1: 26 - Causa provável do acidente | AA1: 27 - Ambientes atingidos - Informações Complementares | AB1: 28 - Identificação da Empresa - Nome | AC1: 29 - Identificação da Empresa - CPF/CNPJ | AD1: 30 - Identificação da Empresa -Licença Ambiental | AE1: 31 - Instituição Atuando - Informações complementares | AF1: 32 - Instituição Atuando - Nome responsável | AG1: 33 - Instituição Atuando - Telefone responsável | AH1: 34 - Ações Tomadas - Possui Plano de Emergência | AI1: 35 - Ações Tomadas - Plano de Emergência acionado | AJ1: 36 - Ações Tomadas - Tomado outras providências | AK1: 37 - Ações Tomadas - Descrição de providências tomadas | AL1: 38 - Informações Gerais - Informações julgadas úteis | AM1: 39 - Identificação Comunicante - Nome | AN1: 40 - Identificação Comunicante - Instituição/Empresa | AO1: 41 - Identificação Comunicante - Cargo/Função Navio/Instalação | AP1: 42 - Identificação Comunicante - Telefone | AQ1: 43 - Identificação Comunicante - E-mail | AR1: 44 - Fonte Informação - Descrição fonte | AS1: 45 - Origem Acidente - Nome do navio | AT1: 46 - Origem Acidente - Nome da instalação | AU1: 47 - Tipo de Produto - Tipo de substância | AV1: 48 - Tipo de Produto - Volume estimado | AW1: 49 - Detalhes acidente - Situação atual da descarga | AX1: 50 Óbitos/ feridos | AY1: 51 Óbitos/ feridos (X) | AZ1: 52 População afetada/evacuada | BA1: 53 População afetada/evacuada (x) | BB1: 54 Suspensão de abastecimento de água | BC1: 55 Suspensão de abastecimento de água (X) | BD1: 56 Rio/ córrego | BE1: 57 Rio/ córrego (X) | BF1: 58 Lago | BG1: 59 Lago (X) | BH1: 60 Mar | BI1: 61 Mar (X) | BJ1: 62 Praia | BK1: 63 Praia (X) | BL1: 64 Solo | BM1: 65 Solo (x) | BN1: 66 Águas subterrâneas | BO1: 67 Águas subterrâneas (X) | BP1: 68 Atmosfera | BQ1: 69 Atmosfera (X) | BR1: 70 Flora | BS1: 71 Flora (X) | BT1: 72 Fauna | BU1: 73 Fauna(X) | BV1: 74 UC Federal | BW1: 75 UC Federal (x) | BX1: 76 UC estadual/ municipal | BY1: 77 UC estadual/ municipal (x) | BZ1: 78 Outro(s) | CA1: 79 Outro(s) (x) | CB1: 80 Sem dano | CC1: 81 Sem dano (x) | CD1: 82 Sem Informação | CE1: 83 IBAMA | CF1: 84 IBAMA (X) | CG1: 85 OEMA | CH1: 86 OEMA (X) | CI1: 87 DEFESA CIVIL | CJ1: 88 DEFESA CIVIL (X) | CK1: 89 CORPO DE BOMBEIROS | CL1: 90 CORPO DE BOMBEIROS (X) | CM1: 91 POLÍCIA RODOVIÁRIA | CN1: 92 POLÍCIA RODOVIÁRIA (X) | CO1: 93 POLÍCIA MILITAR | CP1: 94 POLÍCIA MILITAR (X) | CQ1: 95 POLÍCIA CIVIL | CR1: 96 POLÍCIA CIVIL (X) | CS1: 97 MARINHA DO BRASIL | CT1: 98 MARINHA DO BRASIL (X) | CU1: 99 EMPRESA ESPECIALIZADA EM ATENDIMENTO | CV1: 100 EMPRESA ESPECIALIZADA EM ATENDIMENTO (X) | CW1: 101 EQUIPE DA PRÓPRIA EMPRESA | CX1: 102 EQUIPE DA PRÓPRIA EMPRESA (X) | CY1: 103 SEM INFORMAÇÃO (X) | CZ1: 104 OUTRA (S) | DA1: 105 OUTRA(S) (X) | DB1: 106 Ações Tomadas - Possui Plano de Emergência2 | DC1: 107 Ações Tomadas - Plano de Emergência acionado 2 | DD1: 108 Ações Tomadas - Tomado outras providências2 | DE1: 109 Identificação da Empresa -Licença Ambiental2
A2: 20251246819 | B2: 45658 | C2: null | D2: null | E2: Plataforma | F2: Derramamento de líquidos | J2: Fluido Hidraulico | K2: 0.0022 | L2: M3 | M2: Mar | N2: Outra(s) | O2: Outra(s) fonte(s) | P2: Quarta | Q2: Vespertino | R2: Não | S2: Santos | T2: Campo de Mero - Bacia de Santos | U2: Durante operação de recolhimento do cabo mensageiro do hauser, foi observado uma perda de contenção de aproximadamente 0,0022 m3 de fluido hidráulico (MOBIL DTE 10 EXCEL 32) na conexão flangeada da tubulação hidráulica do sistema de offloading da unidade, resultando na descarga do fluido para o mar. | V2: FLUIDO HIDRÁULICO - 0,0022m³ | Z2: Falha da junta de vedação de conexão hidráulica. Em investigação. | AB2: PETROBRAS | AC2: 33000167000292 | AD2: 1 | AE2: PETROBRAS | AH2: S | AI2: N | AJ2: S | AK2: Paralisação e despressurização do sistema hidráulico, cessando o vazamento imediatamente. Mobilizado embarcação oil rec para varredura (feição não encontrada). | AL2: Processo sei nº #{23565508|02001.000070/2025-40} (Emergência Ambiental: Acidente Ambiental)# [1] Volume descarregado: 0,0022 m³ de fluido hidráulico base óleo; [2] Nome comercial do produto: MOBIL DTE 10 EXCEL 32; [3] Composição química: Destilados (petróleo), parafínicos pesados, tratados com hidrogénio; destilados (petróleo), parafínicos pesados, desparafinados com solventes; [4] Classificação ONU ou IMDG: Não regulado; [5] Ambiente atingido: Mar. | AM2: PETRLEO BRASILEIRO S/A - PETROBRAS | AQ2: giselletinoco@petrobras.com.br | AX2: =IFERROR(FIND("Óbitos/feridos",consulta_completa__11[[#This Row],[13 - Ocorrências/Ambientes Atingidos]]),0) -> 0 | AY2: =IF(AX2=0,"","X") | AZ2: =IFERROR(FIND("População afetada/evacuada",consulta_completa__11[[#This Row],[13 - Ocorrências/Ambientes Atingidos]]),0) -> 0 | BA2: =IF(AZ2=0,"","X") | BB2: =IFERROR(FIND("Suspensão de abastecimento de água",consulta_completa__11[[#This Row],[13 - Ocorrências/Ambientes Atingidos]]),0) -> 0 | BC2: =IF(BB2=0,"","X") | BD2: =IFERROR(FIND("Rio/córrego",consulta_completa__11[[#This Row],[13 - Ocorrências/Ambientes Atingidos]]),0) -> 0 | BE2: =IF(BD2=0,"","X") | BF2: =IFERROR(FIND("Lago",consulta_completa__11[[#This Row],[13 - Ocorrências/Ambientes Atingidos]]),0) -> 0 | BG2: =IF(BF2=0,"","X") | BH2: =IFERROR(FIND("Mar",consulta_completa__11[[#This Row],[13 - Ocorrências/Ambientes Atingidos]]),0) -> 1 | BI2: =IF(BH2=0,"","X") -> X | BJ2: =IFERROR(FIND("Praia",consulta_completa__11[[#This Row],[13 - Ocorrências/Ambientes Atingidos]]),0) -> 0 | BK2: =IF(BJ2=0,"","X") | BL2: =IFERROR(FIND("Solo",consulta_completa__11[[#This Row],[13 - Ocorrências/Ambientes Atingidos]]),0) -> 0 | BM2: =IF(BL2=0,"","X") | BN2: =IFERROR(FIND("Águas subterrâneas",consulta_completa__11[[#This Row],[13 - Ocorrências/Ambientes Atingidos]]),0) -> 0 | BO2: =IF(BN2=0,"","X") | BP2: =IFERROR(FIND("Atmosfera",consulta_completa__11[[#This Row],[13 - Ocorrências/Ambientes Atingidos]]),0) -> 0 | BQ2: =IF(BP2=0,"","X") | BR2: =IFERROR(FIND("Flora",consulta_completa__11[[#This Row],[13 - Ocorrências/Ambientes Atingidos]]),0) -> 0 | BS2: =IF(BR2=0,"","X") | BT2: =IFERROR(FIND("Fauna",consulta_completa__11[[#This Row],[13 - Ocorrências/Ambientes Atingidos]]),0) -> 0 | BU2: =IF(BT2=0,"","X") | BV2: =IFERROR(FIND("UC federal",consulta_completa__11[[#This Row],[13 - Ocorrências/Ambientes Atingidos]]),0) -> 0 | BW2: =IF(BV2=0,"","X") | BX2: =IFERROR(FIND("UC estadual/municipal",consulta_completa__11[[#This Row],[13 - Ocorrências/Ambientes Atingidos]]),0) -> 0 | BY2: =IF(BX2=0,"","X") | BZ2: =IFERROR(FIND("Outro(s)",consulta_completa__11[[#This Row],[13 - Ocorrências/Ambientes Atingidos]]),0) -> 0 | CA2: =IF(BZ2=0,"","X") | CB2: =IFERROR(FIND("Sem dano",consulta_completa__11[[#This Row],[13 - Ocorrências/Ambientes Atingidos]]),0) -> 0 | CC2: =IF(CB2=0,"","X") | CD2: =IF(consulta_completa__11[[#This Row],[13 - Ocorrências/Ambientes Atingidos]]="","X","") | CE2: =IFERROR(FIND("IBAMA",consulta_completa__11[[#This Row],[14 - Inst. Atuando no Local]]),0) -> 0 | CF2: =IF(CE2=0,"","X") | CG2: =IFERROR(FIND("OEMA",consulta_completa__11[[#This Row],[14 - Inst. Atuando no Local]]),0) -> 0 | CH2: =IF(CG2=0,"","X") | CI2: =IFERROR(FIND("DEFESA CIVIL",consulta_completa__11[[#This Row],[14 - Inst. Atuando no Local]]),0) -> 0 | CJ2: =IF(CI2=0,"","X") | CK2: =IFERROR(FIND("CORPO DE BOMBEIROS",consulta_completa__11[[#This Row],[14 - Inst. Atuando no Local]]),0) -> 0 | CL2: =IF(CK2=0,"","X") | CM2: =IFERROR(FIND("POLÍCIA RODOVIÁRIA",consulta_completa__11[[#This Row],[14 - Inst. Atuando no Local]]),0) -> 0 | CN2: =IF(CM2=0,"","X") | CO2: =IFERROR(FIND("POLÍCIA MILITAR",consulta_completa__11[[#This Row],[14 - Inst. Atuando no Local]]),0) -> 0 | CP2: =IF(CO2=0,"","X") | CQ2: =IFERROR(FIND("POLÍCIA CIVIL",consulta_completa__11[[#This Row],[14 - Inst. Atuando no Local]]),0) -> 0 | CR2: =IF(CQ2=0,"","X") | CS2: =IFERROR(FIND("MARINHA DO BRASIL",consulta_completa__11[[#This Row],[14 - Inst. Atuando no Local]]),0) -> 0 | CT2: =IF(CS2=0,"","X") | CU2: =IFERROR(FIND("EMPRESA ESPECIALIZADA EM ATENDIMENTO",consulta_completa__11[[#This Row],[14 - Inst. Atuando no Local]]),0) -> 0 | CV2: =IF(CU2=0,"","X") | CW2: =IFERROR(FIND("IBAMA",consulta_completa__11[[#This Row],[14 - Inst. Atuando no Local]]),0) -> 0 | CX2: =IF(CW2=0,"","X") | CY2: =IF(consulta_completa__11[[#This Row],[14 - Inst. Atuando no Local]]="","X","") | CZ2: =IFERROR(FIND("OUTRA (S)",consulta_completa__11[[#This Row],[14 - Inst. Atuando no Local]]),0) -> 0 | DA2: =IF(CZ2=0,"","X") | DB2: =IF(AH$2="","",IF(AH$2="S","Sim",IF(AH$2="N","Não", IF(AH$2="I","Sem Informação")))) -> Sim | DC2: =IF(AI$2="","",IF(AI$2="S","Sim",IF(AI$2="N","Não", IF(AI$2="I","Sem Informação")))) -> Não | DD2: =IF(AJ$2="","",IF(AJ$2="S","Sim",IF(AJ$2="N","Não", IF(AJ$2="I","Sem Informação")))) -> Sim | DE2: =IF(AD2=1,"Federal",IF(AD2=2,"Estadual",IF(AD2=0,"Sem informação",""))) -> Federal
A3: 20251336008 | B3: 45659 | C3: Governador Dix Sept Rosado | D3: RN | E3: Outro(s) | F3: Outro(s) | M3: Solo | N3: Empresa especializada em atendimento | P3: Quinta | Q3: Matutino | R3: Não | T3: : Locação do poço 7-LOR-38-RN (72100019088), Campo Lorena, Bacia Potiguar | U3: Poço terrestre | V3: No dia 02/01/2025, por volta das 10h10, durante o último estágio do bombeio do Fraturamento, no 7-LOR-38-RN, identificou-se um vazamento no ponto de amostragem de gel. Tentou-se realizar a contenção do fluído, porém como não houve êxito, seguiu-se com o deslocamento e paralisação da operação. | Y3: TRUE | Z3: Furo em válvula de amostragem. | AB3: Potiguar E&P | AD3: 2 | AF3: : Jéssica Luisa Santos da Silva | AG3: 71991321907 | AH3: S | AI3: S | AJ3: S | AK3: Operação paralisada, realizada as devidas comunicações internas, e acionado a equipe de limpeza. | AL3: Processo sei nº 02001.000180/2025-10 (Emergência Ambiental: Acidente Ambiental) 1) 0,72m³. 2) Solo. 3) a 4) N/A. 7) e 8) [aguardando equipe operacional, será retificado]. 4) a 11)N/A. | Volume da perda de contenção: 0,72m³. Metodologia de cálculo = área x lâmina: (36m² x 0,02m) = 0,72m³. | AM3: Jeanei Rodrigues Dos Santos | AN3: Ibama | AO3: Técnico Administrativo | AP3: 61999572720 | AQ3: jeanei.santos@ibama.gov.br | AT3: 7-LOR-38-RN | AU3: Fluidos de perfuração completação a base d'agua | AV3: 7200000000 | AW3: Paralisada | AX3: =IFERROR(FIND("Óbitos/feridos",consulta_completa__11[[#This Row],[13 - Ocorrências/Ambientes Atingidos]]),0) -> 0 | AY3: =IF(AX3=0,"","X") | AZ3: =IFERROR(FIND("População afetada/evacuada",consulta_completa__11[[#This Row],[13 - Ocorrências/Ambientes Atingidos]]),0) -> 0 | BA3: =IF(AZ3=0,"","X") | BB3: =IFERROR(FIND("Suspensão de abastecimento de água",consulta_completa__11[[#This Row],[13 - Ocorrências/Ambientes Atingidos]]),0) -> 0 | BC3: =IF(BB3=0,"","X") | BD3: =IFERROR(FIND("Rio/córrego",consulta_completa__11[[#This Row],[13 - Ocorrências/Ambientes Atingidos]]),0) -> 0 | BE3: =IF(BD3=0,"","X") | BF3: =IFERROR(FIND("Lago",consulta_completa__11[[#This Row],[13 - Ocorrências/Ambientes Atingidos]]),0) -> 0 | BG3: =IF(BF3=0,"","X") | BH3: =IFERROR(FIND("Mar",consulta_completa__11[[#This Row],[13 - Ocorrências/Ambientes Atingidos]]),0) -> 0 | BI3: =IF(BH3=0,"","X") | BJ3: =IFERROR(FIND("Praia",consulta_completa__11[[#This Row],[13 - Ocorrências/Ambientes Atingidos]]),0) -> 0 | BK3: =IF(BJ3=0,"","X") | BL3: =IFERROR(FIND("Solo",consulta_completa__11[[#This Row],[13 - Ocorrências/Ambientes Atingidos]]),0) -> 1 | BM3: =IF(BL3=0,"","X") -> X | BN3: =IFERROR(FIND("Águas subterrâneas",consulta_completa__11[[#This Row],[13 - Ocorrências/Ambientes Atingidos]]),0) -> 0 | BO3: =IF(BN3=0,"","X") | BP3: =IFERROR(FIND("Atmosfera",consulta_completa__11[[#This Row],[13 - Ocorrências/Ambientes Atingidos]]),0) -> 0 | BQ3: =IF(BP3=0,"","X") | BR3: =IFERROR(FIND("Flora",consulta_completa__11[[#This Row],[13 - Ocorrências/Ambientes Atingidos]]),0) -> 0 | BS3: =IF(BR3=0,"","X") | BT3: =IFERROR(FIND("Fauna",consulta_completa__11[[#This Row],[13 - Ocorrências/Ambientes Atingidos]]),0) -> 0 | BU3: =IF(BT3=0,"","X") | BV3: =IFERROR(FIND("UC federal",consulta_completa__11[[#This Row],[13 - Ocorrências/Ambientes Atingidos]]),0) -> 0 | BW3: =IF(BV3=0,"","X") | BX3: =IFERROR(FIND("UC estadual/municipal",consulta_completa__11[[#This Row],[13 - Ocorrências/Ambientes Atingidos]]),0) -> 0 | BY3: =IF(BX3=0,"","X") | BZ3: =IFERROR(FIND("Outro(s)",consulta_completa__11[[#This Row],[13 - Ocorrências/Ambientes Atingidos]]),0) -> 0 | CA3: =IF(BZ3=0,"","X") | CB3: =IFERROR(FIND("Sem dano",consulta_completa__11[[#This Row],[13 - Ocorrências/Ambientes Atingidos]]),0) -> 0 | CC3: =IF(CB3=0,"","X") | CD3: =IF(consulta_completa__11[[#This Row],[13 - Ocorrências/Ambientes Atingidos]]="","X","") | CE3: =IFERROR(FIND("IBAMA",consulta_completa__11[[#This Row],[14 - Inst. Atuando no Local]]),0) -> 0 | CF3: =IF(CE3=0,"","X") | CG3: =IFERROR(FIND("OEMA",consulta_completa__11[[#This Row],[14 - Inst. Atuando no Local]]),0) -> 0 | CH3: =IF(CG3=0,"","X") | CI3: =IFERROR(FIND("DEFESA CIVIL",consulta_completa__11[[#This Row],[14 - Inst. Atuando no Local]]),0) -> 0 | CJ3: =IF(CI3=0,"","X") | CK3: =IFERROR(FIND("CORPO DE BOMBEIROS",consulta_completa__11[[#This Row],[14 - Inst. Atuando no Local]]),0) -> 0 | CL3: =IF(CK3=0,"","X") | CM3: =IFERROR(FIND("POLÍCIA RODOVIÁRIA",consulta_completa__11[[#This Row],[14 - Inst. Atuando no Local]]),0) -> 0 | CN3: =IF(CM3=0,"","X") | CO3: =IFERROR(FIND("POLÍCIA MILITAR",consulta_completa__11[[#This Row],[14 - Inst. Atuando no Local]]),0) -> 0 | CP3: =IF(CO3=0,"","X") | CQ3: =IFERROR(FIND("POLÍCIA CIVIL",consulta_completa__11[[#This Row],[14 - Inst. Atuando no Local]]),0) -> 0 | CR3: =IF(CQ3=0,"","X") | CS3: =IFERROR(FIND("MARINHA DO BRASIL",consulta_completa__11[[#This Row],[14 - Inst. Atuando no Local]]),0) -> 0 | CT3: =IF(CS3=0,"","X") | CU3: =IFERROR(FIND("EMPRESA ESPECIALIZADA EM ATENDIMENTO",consulta_completa__11[[#This Row],[14 - Inst. Atuando no Local]]),0) -> 0 | CV3: =IF(CU3=0,"","X") | CW3: =IFERROR(FIND("IBAMA",consulta_completa__11[[#This Row],[14 - Inst. Atuando no Local]]),0) -> 0 | CX3: =IF(CW3=0,"","X") | CY3: =IF(consulta_completa__11[[#This Row],[14 - Inst. Atuando no Local]]="","X","") | CZ3: =IFERROR(FIND("OUTRA (S)",consulta_completa__11[[#This Row],[14 - Inst. Atuando no Local]]),0) -> 0 | DA3: =IF(CZ3=0,"","X") | DB3: =IF(AH$2="","",IF(AH$2="S","Sim",IF(AH$2="N","Não", IF(AH$2="I","Sem Informação")))) -> Sim | DC3: =IF(AI$2="","",IF(AI$2="S","Sim",IF(AI$2="N","Não", IF(AI$2="I","Sem Informação")))) -> Não | DD3: =IF(AJ$2="","",IF(AJ$2="S","Sim",IF(AJ$2="N","Não", IF(AJ$2="I","Sem Informação")))) -> Sim | DE3: =IF(AD3=1,"Federal",IF(AD3=2,"Estadual",IF(AD3=0,"Sem informação",""))) -> Estadual
A4: 20251336012 | B4: 45659 | C4: Cubatão | D4: SP | E4: Ferrovia | F4: Lançamento de sólidos | J4: Cloreto de Potássio | K4: 4 | L4: T | M4: Solo | N4: Outra(s) | O4: Outra(s) fonte(s) | P4: Quinta | Q4: Noturno | R4: Não | U4: Vandalismo na ferrovia com abertura de bicas em vagão graneleiro carregado fertilizante. | V4: Vandalismo com abertura de vagão graneleiro carregado com Fertilizante (Cloreto de Potassio). Lançamento de 4 toneladas de fertilizante granular sobre a linha férrea | Z4: Ato criminoso caracterizado pela abertura de bicas em vagão graneleiro ferroviário carregado com fertilizante granular. | AA4: Solo dentro dos limites da área de domínio da via férrea. | AB4: Rumo Logistica S. A. | AC4: 02502844000166 | AD4: 1 | AE4: Equipes de atendimento de limpeza, contratadas pela Rumo, atuando no trecho afetado. | AH4: S | AI4: N | AJ4: S | AK4: Equipes de atendimento emergêncial de limpeza, contratadas pela rumo, e de segurança patrimonial, atuando no trecho afetado para remoção do material, liberação da via e garantia da segurança dos trabalhadores. | AM4: Eloisa Caxias Coelho | AN4: Rumo Logistica S. A. | AO4: Auditor Ambiental | AP4: 41988207121 | AQ4: eloisa.coelho@rumolog.com | AX4: =IFERROR(FIND("Óbitos/feridos",consulta_completa__11[[#This Row],[13 - Ocorrências/Ambientes Atingidos]]),0) -> 0 | AY4: =IF(AX4=0,"","X") | AZ4: =IFERROR(FIND("População afetada/evacuada",consulta_completa__11[[#This Row],[13 - Ocorrências/Ambientes Atingidos]]),0) -> 0 | BA4: =IF(AZ4=0,"","X") | BB4: =IFERROR(FIND("Suspensão de abastecimento de água",consulta_completa__11[[#This Row],[13 - Ocorrências/Ambientes Atingidos]]),0) -> 0 | BC4: =IF(BB4=0,"","X") | BD4: =IFERROR(FIND("Rio/córrego",consulta_completa__11[[#This Row],[13 - Ocorrências/Ambientes Atingidos]]),0) -> 0 | BE4: =IF(BD4=0,"","X") | BF4: =IFERROR(FIND("Lago",consulta_completa__11[[#This Row],[13 - Ocorrências/Ambientes Atingidos]]),0) -> 0 | BG4: =IF(BF4=0,"","X") | BH4: =IFERROR(FIND("Mar",consulta_completa__11[[#This Row],[13 - Ocorrências/Ambientes Atingidos]]),0) -> 0 | BI4: =IF(BH4=0,"","X") | BJ4: =IFERROR(FIND("Praia",consulta_completa__11[[#This Row],[13 - Ocorrências/Ambientes Atingidos]]),0) -> 0 | BK4: =IF(BJ4=0,"","X") | BL4: =IFERROR(FIND("Solo",consulta_completa__11[[#This Row],[13 - Ocorrências/Ambientes Atingidos]]),0) -> 1 | BM4: =IF(BL4=0,"","X") -> X | BN4: =IFERROR(FIND("Águas subterrâneas",consulta_completa__11[[#This Row],[13 - Ocorrências/Ambientes Atingidos]]),0) -> 0 | BO4: =IF(BN4=0,"","X") | BP4: =IFERROR(FIND("Atmosfera",consulta_completa__11[[#This Row],[13 - Ocorrências/Ambientes Atingidos]]),0) -> 0 | BQ4: =IF(BP4=0,"","X") | BR4: =IFERROR(FIND("Flora",consulta_completa__11[[#This Row],[13 - Ocorrências/Ambientes Atingidos]]),0) -> 0 | BS4: =IF(BR4=0,"","X") | BT4: =IFERROR(FIND("Fauna",consulta_completa__11[[#This Row],[13 - Ocorrências/Ambientes Atingidos]]),0) -> 0 | BU4: =IF(BT4=0,"","X") | BV4: =IFERROR(FIND("UC federal",consulta_completa__11[[#This Row],[13 - Ocorrências/Ambientes Atingidos]]),0) -> 0 | BW4: =IF(BV4=0,"","X") | BX4: =IFERROR(FIND("UC estadual/municipal",consulta_completa__11[[#This Row],[13 - Ocorrências/Ambientes Atingidos]]),0) -> 0 | BY4: =IF(BX4=0,"","X") | BZ4: =IFERROR(FIND("Outro(s)",consulta_completa__11[[#This Row],[13 - Ocorrências/Ambientes Atingidos]]),0) -> 0 | CA4: =IF(BZ4=0,"","X") | CB4: =IFERROR(FIND("Sem dano",consulta_completa__11[[#This Row],[13 - Ocorrências/Ambientes Atingidos]]),0) -> 0 | CC4: =IF(CB4=0,"","X") | CD4: =IF(consulta_completa__11[[#This Row],[13 - Ocorrências/Ambientes Atingidos]]="","X","") | CE4: =IFERROR(FIND("IBAMA",consulta_completa__11[[#This Row],[14 - Inst. Atuando no Local]]),0) -> 0 | CF4: =IF(CE4=0,"","X") | CG4: =IFERROR(FIND("OEMA",consulta_completa__11[[#This Row],[14 - Inst. Atuando no Local]]),0) -> 0 | CH4: =IF(CG4=0,"","X") | CI4: =IFERROR(FIND("DEFESA CIVIL",consulta_completa__11[[#This Row],[14 - Inst. Atuando no Local]]),0) -> 0 | CJ4: =IF(CI4=0,"","X") | CK4: =IFERROR(FIND("CORPO DE BOMBEIROS",consulta_completa__11[[#This Row],[14 - Inst. Atuando no Local]]),0) -> 0 | CL4: =IF(CK4=0,"","X") | CM4: =IFERROR(FIND("POLÍCIA RODOVIÁRIA",consulta_completa__11[[#This Row],[14 - Inst. Atuando no Local]]),0) -> 0 | CN4: =IF(CM4=0,"","X") | CO4: =IFERROR(FIND("POLÍCIA MILITAR",consulta_completa__11[[#This Row],[14 - Inst. Atuando no Local]]),0) -> 0 | CP4: =IF(CO4=0,"","X") | CQ4: =IFERROR(FIND("POLÍCIA CIVIL",consulta_completa__11[[#This Row],[14 - Inst. Atuando no Local]]),0) -> 0 | CR4: =IF(CQ4=0,"","X") | CS4: =IFERROR(FIND("MARINHA DO BRASIL",consulta_completa__11[[#This Row],[14 - Inst. Atuando no Local]]),0) -> 0 | CT4: =IF(CS4=0,"","X") | CU4: =IFERROR(FIND("EMPRESA ESPECIALIZADA EM ATENDIMENTO",consulta_completa__11[[#This Row],[14 - Inst. Atuando no Local]]),0) -> 0 | CV4: =IF(CU4=0,"","X") | CW4: =IFERROR(FIND("IBAMA",consulta_completa__11[[#This Row],[14 - Inst. Atuando no Local]]),0) -> 0 | CX4: =IF(CW4=0,"","X") | CY4: =IF(consulta_completa__11[[#This Row],[14 - Inst. Atuando no Local]]="","X","") | CZ4: =IFERROR(FIND("OUTRA (S)",consulta_completa__11[[#This Row],[14 - Inst. Atuando no Local]]),0) -> 0 | DA4: =IF(CZ4=0,"","X") | DB4: =IF(AH$2="","",IF(AH$2="S","Sim",IF(AH$2="N","Não", IF(AH$2="I","Sem Informação")))) -> Sim | DC4: =IF(AI$2="","",IF(AI$2="S","Sim",IF(AI$2="N","Não", IF(AI$2="I","Sem Informação")))) -> Não | DD4: =IF(AJ$2="","",IF(AJ$2="S","Sim",IF(AJ$2="N","Não", IF(AJ$2="I","Sem Informação")))) -> Sim | DE4: =IF(AD4=1,"Federal",IF(AD4=2,"Estadual",IF(AD4=0,"Sem informação",""))) -> Federal
A5: 20252525226 | B5: 45659 | C5: Betim | D5: MG | E5: Indústria | F5: Vazamento de gases | G5: AMÔNIA, ANIDRA | M5: Outro(s) | N5: Outra(s); Corpo de Bombeiros | O5: Órgão Estadual ou Municipal de Meio Ambiente | P5: Quinta | Q5: Noturno | R5: Não | T5: Av. Nova York, 94 - Capelinha | U5: Conforme relatado ao NEA, houve o vazamento de gás amônia, na Sala de Máquinas, decorrente do rompimento de selo mecânico de uma bomba responsável pelo bombeamento de amônia. O frigorífico foi completamente evacuado e segundo informações, não houve vítimas. Houve o fechamento das válvulas das tubulações de alimentação das bombas bem como substituição da bomba afetada. As ações contaram com atuação da brigada interna e do Corpo de Bombeiros. | V5: Vazamento de gás amônia | Z5: Rompimento de selo mecânico de uma bomba | AA5: Ambiente do empreendimento. | AB5: GRANJA BRASILIA AGROINDUSTRIAL AVICOLA LTDA | AC5: 07150233001000 | AD5: 2 | AE5: Brigada interna | AH5: I | AI5: N | AJ5: S | AK5: O frigorífico foi completamente evacuado e segundo informações, não houve vítimas. Houve o fechamento das válvulas das tubulações de alimentação das bombas bem como substituição da bomba afetada. A | AM5: Cleiton Lopes Ribeiro | AQ5: cleiton.ribeiro@ibama.gov.br | AX5: =IFERROR(FIND("Óbitos/feridos",consulta_completa__11[[#This Row],[13 - Ocorrências/Ambientes Atingidos]]),0) -> 0 | AY5: =IF(AX5=0,"","X") | AZ5: =IFERROR(FIND("População afetada/evacuada",consulta_completa__11[[#This Row],[13 - Ocorrências/Ambientes Atingidos]]),0) -> 0 | BA5: =IF(AZ5=0,"","X") | BB5: =IFERROR(FIND("Suspensão de abastecimento de água",consulta_completa__11[[#This Row],[13 - Ocorrências/Ambientes Atingidos]]),0) -> 0 | BC5: =IF(BB5=0,"","X") | BD5: =IFERROR(FIND("Rio/córrego",consulta_completa__11[[#This Row],[13 - Ocorrências/Ambientes Atingidos]]),0) -> 0 | BE5: =IF(BD5=0,"","X") | BF5: =IFERROR(FIND("Lago",consulta_completa__11[[#This Row],[13 - Ocorrências/Ambientes Atingidos]]),0) -> 0 | BG5: =IF(BF5=0,"","X") | BH5: =IFERROR(FIND("Mar",consulta_completa__11[[#This Row],[13 - Ocorrências/Ambientes Atingidos]]),0) -> 0 | BI5: =IF(BH5=0,"","X") | BJ5: =IFERROR(FIND("Praia",consulta_completa__11[[#This Row],[13 - Ocorrências/Ambientes Atingidos]]),0) -> 0 | BK5: =IF(BJ5=0,"","X") | BL5: =IFERROR(FIND("Solo",consulta_completa__11[[#This Row],[13 - Ocorrências/Ambientes Atingidos]]),0) -> 0 | BM5: =IF(BL5=0,"","X") | BN5: =IFERROR(FIND("Águas subterrâneas",consulta_completa__11[[#This Row],[13 - Ocorrências/Ambientes Atingidos]]),0) -> 0 | BO5: =IF(BN5=0,"","X") | BP5: =IFERROR(FIND("Atmosfera",consulta_completa__11[[#This Row],[13 - Ocorrências/Ambientes Atingidos]]),0) -> 0 | BQ5: =IF(BP5=0,"","X") | BR5: =IFERROR(FIND("Flora",consulta_completa__11[[#This Row],[13 - Ocorrências/Ambientes Atingidos]]),0) -> 0 | BS5: =IF(BR5=0,"","X") | BT5: =IFERROR(FIND("Fauna",consulta_completa__11[[#This Row],[13 - Ocorrências/Ambientes Atingidos]]),0) -> 0 | BU5: =IF(BT5=0,"","X") | BV5: =IFERROR(FIND("UC federal",consulta_completa__11[[#This Row],[13 - Ocorrências/Ambientes Atingidos]]),0) -> 0 | BW5: =IF(BV5=0,"","X") | BX5: =IFERROR(FIND("UC estadual/municipal",consulta_completa__11[[#This Row],[13 - Ocorrências/Ambientes Atingidos]]),0) -> 0 | BY5: =IF(BX5=0,"","X") | BZ5: =IFERROR(FIND("Outro(s)",consulta_completa__11[[#This Row],[13 - Ocorrências/Ambientes Atingidos]]),0) -> 1 | CA5: =IF(BZ5=0,"","X") -> X | CB5: =IFERROR(FIND("Sem dano",consulta_completa__11[[#This Row],[13 - Ocorrências/Ambientes Atingidos]]),0) -> 0 | CC5: =IF(CB5=0,"","X") | CD5: =IF(consulta_completa__11[[#This Row],[13 - Ocorrências/Ambientes Atingidos]]="","X","") | CE5: =IFERROR(FIND("IBAMA",consulta_completa__11[[#This Row],[14 - Inst. Atuando no Local]]),0) -> 0 | CF5: =IF(CE5=0,"","X") | CG5: =IFERROR(FIND("OEMA",consulta_completa__11[[#This Row],[14 - Inst. Atuando no Local]]),0) -> 0 | CH5: =IF(CG5=0,"","X") | CI5: =IFERROR(FIND("DEFESA CIVIL",consulta_completa__11[[#This Row],[14 - Inst. Atuando no Local]]),0) -> 0 | CJ5: =IF(CI5=0,"","X") | CK5: =IFERROR(FIND("CORPO DE BOMBEIROS",consulta_completa__11[[#This Row],[14 - Inst. Atuando no Local]]),0) -> 0 | CL5: =IF(CK5=0,"","X") | CM5: =IFERROR(FIND("POLÍCIA RODOVIÁRIA",consulta_completa__11[[#This Row],[14 - Inst. Atuando no Local]]),0) -> 0 | CN5: =IF(CM5=0,"","X") | CO5: =IFERROR(FIND("POLÍCIA MILITAR",consulta_completa__11[[#This Row],[14 - Inst. Atuando no Local]]),0) -> 0 | CP5: =IF(CO5=0,"","X") | CQ5: =IFERROR(FIND("POLÍCIA CIVIL",consulta_completa__11[[#This Row],[14 - Inst. Atuando no Local]]),0) -> 0 | CR5: =IF(CQ5=0,"","X") | CS5: =IFERROR(FIND("MARINHA DO BRASIL",consulta_completa__11[[#This Row],[14 - Inst. Atuando no Local]]),0) -> 0 | CT5: =IF(CS5=0,"","X") | CU5: =IFERROR(FIND("EMPRESA ESPECIALIZADA EM ATENDIMENTO",consulta_completa__11[[#This Row],[14 - Inst. Atuando no Local]]),0) -> 0 | CV5: =IF(CU5=0,"","X") | CW5: =IFERROR(FIND("IBAMA",consulta_completa__11[[#This Row],[14 - Inst. Atuando no Local]]),0) -> 0 | CX5: =IF(CW5=0,"","X") | CY5: =IF(consulta_completa__11[[#This Row],[14 - Inst. Atuando no Local]]="","X","") | CZ5: =IFERROR(FIND("OUTRA (S)",consulta_completa__11[[#This Row],[14 - Inst. Atuando no Local]]),0) -> 0 | DA5: =IF(CZ5=0,"","X") | DB5: =IF(AH$2="","",IF(AH$2="S","Sim",IF(AH$2="N","Não", IF(AH$2="I","Sem Informação")))) -> Sim | DC5: =IF(AI$2="","",IF(AI$2="S","Sim",IF(AI$2="N","Não", IF(AI$2="I","Sem Informação")))) -> Não | DD5: =IF(AJ$2="","",IF(AJ$2="S","Sim",IF(AJ$2="N","Não", IF(AJ$2="I","Sem Informação")))) -> Sim | DE5: =IF(AD5=1,"Federal",IF(AD5=2,"Estadual",IF(AD5=0,"Sem informação",""))) -> Estadual
A6: 2025143653 | B6: 45660 | C6: null | D6: null | E6: Outro(s) | F6: Derramamento de líquidos | J6: Etilenoglicol | K6: 0.000132 | L6: M3 | M6: Mar | N6: Outra(s) | O6: Outra(s) fonte(s) | P6: Sexta | Q6: Matutino | R6: Não | S6: Campos | T6: Campo de Jubarte - Bacia de Campos | U6: [EMBARCAÇÃO AKER WAYFARER]: Durante operação visando dissociação de hidratos com suporte de embarcação, foi observada uma queda abrupta de pressão na linha de alimentação de MEG (Etilenoglicol). Após inspeção detalhada no conjunto da ANM (árvore de natal molhada), foi identificado ponto de escape na mangueira que conecta a ferramenta ao equipamento submarino de teste. O vazamento foi estimado em 0,000132 m³. | V6: GLICOL - 0,000132 m3. | Z6: Perda de contenção da mangueira do sistema de alimentação de MEG. | AB6: Petrobras | AC6: 33000167100750 | AD6: 1 | AE6: PETROBRAS | AH6: S | AI6: N | AJ6: S | AK6: 1 - Drenada pressão da linha HCR (mangueira de alta resistência ao colapso) para interrupção do escape. 2 - Desconexão da linha HCR para subida do skid de remediação e troca da mangueira HCR. | AL6: - Cálculo da estimativa do volume: A mangueira HCR tem 28 metros, que correspondem a 3,7 litros. O furo na mangueira está posicionado a 1 metro do ponto de ligação na ANM. Considerando que todo o volume desse 1 metro escapou, chegamos ao volume de 0,132 litros. - Volume descarregado no mar: 0,000132 m3; - Nome comercial: ETILENO GLICOL (MEG); - Composição química: Etileno glicol. - ONU/IMDG: Não classificado como perigoso. | AM6: PETROBRAS - PETROLEO BRASILEIRO S.A. | AQ6: crisguerreiro@petrobras.com.br | AX6: =IFERROR(FIND("Óbitos/feridos",consulta_completa__11[[#This Row],[13 - Ocorrências/Ambientes Atingidos]]),0) -> 0 | AY6: =IF(AX6=0,"","X") | AZ6: =IFERROR(FIND("População afetada/evacuada",consulta_completa__11[[#This Row],[13 - Ocorrências/Ambientes Atingidos]]),0) -> 0 | BA6: =IF(AZ6=0,"","X") | BB6: =IFERROR(FIND("Suspensão de abastecimento de água",consulta_completa__11[[#This Row],[13 - Ocorrências/Ambientes Atingidos]]),0) -> 0 | BC6: =IF(BB6=0,"","X") | BD6: =IFERROR(FIND("Rio/córrego",consulta_completa__11[[#This Row],[13 - Ocorrências/Ambientes Atingidos]]),0) -> 0 | BE6: =IF(BD6=0,"","X") | BF6: =IFERROR(FIND("Lago",consulta_completa__11[[#This Row],[13 - Ocorrências/Ambientes Atingidos]]),0) -> 0 | BG6: =IF(BF6=0,"","X") | BH6: =IFERROR(FIND("Mar",consulta_completa__11[[#This Row],[13 - Ocorrências/Ambientes Atingidos]]),0) -> 1 | BI6: =IF(BH6=0,"","X") -> X | BJ6: =IFERROR(FIND("Praia",consulta_completa__11[[#This Row],[13 - Ocorrências/Ambientes Atingidos]]),0) -> 0 | BK6: =IF(BJ6=0,"","X") | BL6: =IFERROR(FIND("Solo",consulta_completa__11[[#This Row],[13 - Ocorrências/Ambientes Atingidos]]),0) -> 0 | BM6: =IF(BL6=0,"","X") | BN6: =IFERROR(FIND("Águas subterrâneas",consulta_completa__11[[#This Row],[13 - Ocorrências/Ambientes Atingidos]]),0) -> 0 | BO6: =IF(BN6=0,"","X") | BP6: =IFERROR(FIND("Atmosfera",consulta_completa__11[[#This Row],[13 - Ocorrências/Ambientes Atingidos]]),0) -> 0 | BQ6: =IF(BP6=0,"","X") | BR6: =IFERROR(FIND("Flora",consulta_completa__11[[#This Row],[13 - Ocorrências/Ambientes Atingidos]]),0) -> 0 | BS6: =IF(BR6=0,"","X") | BT6: =IFERROR(FIND("Fauna",consulta_completa__11[[#This Row],[13 - Ocorrências/Ambientes Atingidos]]),0) -> 0 | BU6: =IF(BT6=0,"","X") | BV6: =IFERROR(FIND("UC federal",consulta_completa__11[[#This Row],[13 - Ocorrências/Ambientes Atingidos]]),0) -> 0 | BW6: =IF(BV6=0,"","X") | BX6: =IFERROR(FIND("UC estadual/municipal",consulta_completa__11[[#This Row],[13 - Ocorrências/Ambientes Atingidos]]),0) -> 0 | BY6: =IF(BX6=0,"","X") | BZ6: =IFERROR(FIND("Outro(s)",consulta_completa__11[[#This Row],[13 - Ocorrências/Ambientes Atingidos]]),0) -> 0 | CA6: =IF(BZ6=0,"","X") | CB6: =IFERROR(FIND("Sem dano",consulta_completa__11[[#This Row],[13 - Ocorrências/Ambientes Atingidos]]),0) -> 0 | CC6: =IF(CB6=0,"","X") | CD6: =IF(consulta_completa__11[[#This Row],[13 - Ocorrências/Ambientes Atingidos]]="","X","") | CE6: =IFERROR(FIND("IBAMA",consulta_completa__11[[#This Row],[14 - Inst. Atuando no Local]]),0) -> 0 | CF6: =IF(CE6=0,"","X") | CG6: =IFERROR(FIND("OEMA",consulta_completa__11[[#This Row],[14 - Inst. Atuando no Local]]),0) -> 0 | CH6: =IF(CG6=0,"","X") | CI6: =IFERROR(FIND("DEFESA CIVIL",consulta_completa__11[[#This Row],[14 - Inst. Atuando no Local]]),0) -> 0 | CJ6: =IF(CI6=0,"","X") | CK6: =IFERROR(FIND("CORPO DE BOMBEIROS",consulta_completa__11[[#This Row],[14 - Inst. Atuando no Local]]),0) -> 0 | CL6: =IF(CK6=0,"","X") | CM6: =IFERROR(FIND("POLÍCIA RODOVIÁRIA",consulta_completa__11[[#This Row],[14 - Inst. Atuando no Local]]),0) -> 0 | CN6: =IF(CM6=0,"","X") | CO6: =IFERROR(FIND("POLÍCIA MILITAR",consulta_completa__11[[#This Row],[14 - Inst. Atuando no Local]]),0) -> 0 | CP6: =IF(CO6=0,"","X") | CQ6: =IFERROR(FIND("POLÍCIA CIVIL",consulta_completa__11[[#This Row],[14 - Inst. Atuando no Local]]),0) -> 0 | CR6: =IF(CQ6=0,"","X") | CS6: =IFERROR(FIND("MARINHA DO BRASIL",consulta_completa__11[[#This Row],[14 - Inst. Atuando no Local]]),0) -> 0 | CT6: =IF(CS6=0,"","X") | CU6: =IFERROR(FIND("EMPRESA ESPECIALIZADA EM ATENDIMENTO",consulta_completa__11[[#This Row],[14 - Inst. Atuando no Local]]),0) -> 0 | CV6: =IF(CU6=0,"","X") | CW6: =IFERROR(FIND("IBAMA",consulta_completa__11[[#This Row],[14 - Inst. Atuando no Local]]),0) -> 0 | CX6: =IF(CW6=0,"","X") | CY6: =IF(consulta_completa__11[[#This Row],[14 - Inst. Atuando no Local]]="","X","") | CZ6: =IFERROR(FIND("OUTRA (S)",consulta_completa__11[[#This Row],[14 - Inst. Atuando no Local]]),0) -> 0 | DA6: =IF(CZ6=0,"","X") | DB6: =IF(AH$2="","",IF(AH$2="S","Sim",IF(AH$2="N","Não", IF(AH$2="I","Sem Informação")))) -> Sim | DC6: =IF(AI$2="","",IF(AI$2="S","Sim",IF(AI$2="N","Não", IF(AI$2="I","Sem Informação")))) -> Não | DD6: =IF(AJ$2="","",IF(AJ$2="S","Sim",IF(AJ$2="N","Não", IF(AJ$2="I","Sem Informação")))) -> Sim | DE6: =IF(AD6=1,"Federal",IF(AD6=2,"Estadual",IF(AD6=0,"Sem informação",""))) -> Federal
A7: 2025143658 | B7: 45660 | C7: null | D7: RJ | E7: Outro(s) | F7: Derramamento de líquidos | J7: Fluido Hidraulico | K7: 0.001 | L7: M3 | M7: Mar | N7: Outra(s) | O7: Outra(s) fonte(s) | P7: Sexta | Q7: Matutino | R7: Não | S7: Campos | T7: Campo de Congro, Bacia de Campos | U7: [SS-45 (ATLANTIC STAR) em operação no poço 7-CG-5HPA-RJS ]: Na tentativa de abertura da válvula XO (cross over) da ANM (árvore de natal molhada) hidraulicamente, foi observada com auxílio do ROV (veículo de operação remota), descarga estimada de 0,001 m3 de fluido hidráulico base aquosa, Oceanic HW-525 P, pelo atuador da válvula para o fundo do mar. Interrompida atuação hidráulica e cessada descarga. | V7: FLUIDO HIDRÁULICO - 0,001m³ | Z7: Falha de estanqueidade das vedações do atuador hidráulico da XO da ANM. | AB7: Petrobras | AC7: 33000167100750 | AD7: 1 | AE7: Petrobras | AH7: S | AI7: N | AJ7: S | AK7: Após observação da descarga de fluido, interrompida a tentativa de abertura da válvula hidraulicamente. | AL7: - Volume descarregado: 0,001 m3 (1 litro), estimado pelo volume da linha hidráulica da função do carretel do umbilical (ID 1/4") da superfície até o nível de equalização com lâmina d'água (peso do fluido 8,67 lb/gal, peso da água do mar 8,55 lb/gal). - Descarga de Fluido hidráulico base aquosa Oceanic HW 525 P para o mar. - Composição: água, etileno glicol (CAS 107-21- 1): 20 a 30%; 2-butóxietanol (CAS 111-76-2): 4 a 6%. - ONU/IMDG: Não classificado como perigoso. | AM7: PETROBRAS - PETROLEO BRASILEIRO S.A. | AQ7: crisguerreiro@petrobras.com.br | AX7: =IFERROR(FIND("Óbitos/feridos",consulta_completa__11[[#This Row],[13 - Ocorrências/Ambientes Atingidos]]),0) -> 0 | AY7: =IF(AX7=0,"","X") | AZ7: =IFERROR(FIND("População afetada/evacuada",consulta_completa__11[[#This Row],[13 - Ocorrências/Ambientes Atingidos]]),0) -> 0 | BA7: =IF(AZ7=0,"","X") | BB7: =IFERROR(FIND("Suspensão de abastecimento de água",consulta_completa__11[[#This Row],[13 - Ocorrências/Ambientes Atingidos]]),0) -> 0 | BC7: =IF(BB7=0,"","X") | BD7: =IFERROR(FIND("Rio/córrego",consulta_completa__11[[#This Row],[13 - Ocorrências/Ambientes Atingidos]]),0) -> 0 | BE7: =IF(BD7=0,"","X") | BF7: =IFERROR(FIND("Lago",consulta_completa__11[[#This Row],[13 - Ocorrências/Ambientes Atingidos]]),0) -> 0 | BG7: =IF(BF7=0,"","X") | BH7: =IFERROR(FIND("Mar",consulta_completa__11[[#This Row],[13 - Ocorrências/Ambientes Atingidos]]),0) -> 1 | BI7: =IF(BH7=0,"","X") -> X | BJ7: =IFERROR(FIND("Praia",consulta_completa__11[[#This Row],[13 - Ocorrências/Ambientes Atingidos]]),0) -> 0 | BK7: =IF(BJ7=0,"","X") | BL7: =IFERROR(FIND("Solo",consulta_completa__11[[#This Row],[13 - Ocorrências/Ambientes Atingidos]]),0) -> 0 | BM7: =IF(BL7=0,"","X") | BN7: =IFERROR(FIND("Águas subterrâneas",consulta_completa__11[[#This Row],[13 - Ocorrências/Ambientes Atingidos]]),0) -> 0 | BO7: =IF(BN7=0,"","X") | BP7: =IFERROR(FIND("Atmosfera",consulta_completa__11[[#This Row],[13 - Ocorrências/Ambientes Atingidos]]),0) -> 0 | BQ7: =IF(BP7=0,"","X") | BR7: =IFERROR(FIND("Flora",consulta_completa__11[[#This Row],[13 - Ocorrências/Ambientes Atingidos]]),0) -> 0 | BS7: =IF(BR7=0,"","X") | BT7: =IFERROR(FIND("Fauna",consulta_completa__11[[#This Row],[13 - Ocorrências/Ambientes Atingidos]]),0) -> 0 | BU7: =IF(BT7=0,"","X") | BV7: =IFERROR(FIND("UC federal",consulta_completa__11[[#This Row],[13 - Ocorrências/Ambientes Atingidos]]),0) -> 0 | BW7: =IF(BV7=0,"","X") | BX7: =IFERROR(FIND("UC estadual/municipal",consulta_completa__11[[#This Row],[13 - Ocorrências/Ambientes Atingidos]]),0) -> 0 | BY7: =IF(BX7=0,"","X") | BZ7: =IFERROR(FIND("Outro(s)",consulta_completa__11[[#This Row],[13 - Ocorrências/Ambientes Atingidos]]),0) -> 0 | CA7: =IF(BZ7=0,"","X") | CB7: =IFERROR(FIND("Sem dano",consulta_completa__11[[#This Row],[13 - Ocorrências/Ambientes Atingidos]]),0) -> 0 | CC7: =IF(CB7=0,"","X") | CD7: =IF(consulta_completa__11[[#This Row],[13 - Ocorrências/Ambientes Atingidos]]="","X","") | CE7: =IFERROR(FIND("IBAMA",consulta_completa__11[[#This Row],[14 - Inst. Atuando no Local]]),0) -> 0 | CF7: =IF(CE7=0,"","X") | CG7: =IFERROR(FIND("OEMA",consulta_completa__11[[#This Row],[14 - Inst. Atuando no Local]]),0) -> 0 | CH7: =IF(CG7=0,"","X") | CI7: =IFERROR(FIND("DEFESA CIVIL",consulta_completa__11[[#This Row],[14 - Inst. Atuando no Local]]),0) -> 0 | CJ7: =IF(CI7=0,"","X") | CK7: =IFERROR(FIND("CORPO DE BOMBEIROS",consulta_completa__11[[#This Row],[14 - Inst. Atuando no Local]]),0) -> 0 | CL7: =IF(CK7=0,"","X") | CM7: =IFERROR(FIND("POLÍCIA RODOVIÁRIA",consulta_completa__11[[#This Row],[14 - Inst. Atuando no Local]]),0) -> 0 | CN7: =IF(CM7=0,"","X") | CO7: =IFERROR(FIND("POLÍCIA MILITAR",consulta_completa__11[[#This Row],[14 - Inst. Atuando no Local]]),0) -> 0 | CP7: =IF(CO7=0,"","X") | CQ7: =IFERROR(FIND("POLÍCIA CIVIL",consulta_completa__11[[#This Row],[14 - Inst. Atuando no Local]]),0) -> 0 | CR7: =IF(CQ7=0,"","X") | CS7: =IFERROR(FIND("MARINHA DO BRASIL",consulta_completa__11[[#This Row],[14 - Inst. Atuando no Local]]),0) -> 0 | CT7: =IF(CS7=0,"","X") | CU7: =IFERROR(FIND("EMPRESA ESPECIALIZADA EM ATENDIMENTO",consulta_completa__11[[#This Row],[14 - Inst. Atuando no Local]]),0) -> 0 | CV7: =IF(CU7=0,"","X") | CW7: =IFERROR(FIND("IBAMA",consulta_completa__11[[#This Row],[14 - Inst. Atuando no Local]]),0) -> 0 | CX7: =IF(CW7=0,"","X") | CY7: =IF(consulta_completa__11[[#This Row],[14 - Inst. Atuando no Local]]="","X","") | CZ7: =IFERROR(FIND("OUTRA (S)",consulta_completa__11[[#This Row],[14 - Inst. Atuando no Local]]),0) -> 0 | DA7: =IF(CZ7=0,"","X") | DB7: =IF(AH$2="","",IF(AH$2="S","Sim",IF(AH$2="N","Não", IF(AH$2="I","Sem Informação")))) -> Sim | DC7: =IF(AI$2="","",IF(AI$2="S","Sim",IF(AI$2="N","Não", IF(AI$2="I","Sem Informação")))) -> Não | DD7: =IF(AJ$2="","",IF(AJ$2="S","Sim",IF(AJ$2="N","Não", IF(AJ$2="I","Sem Informação")))) -> Sim | DE7: =IF(AD7=1,"Federal",IF(AD7=2,"Estadual",IF(AD7=0,"Sem informação",""))) -> Federal
A8: 20251336027 | B8: 45660 | C8: Praia Grande | D8: SP | E8: Ferrovia | F8: Lançamento de sólidos | J8: Cloreto de Potássio | K8: 10 | L8: T | M8: Solo | N8: Outra(s) | O8: Outra(s) fonte(s) | P8: Sexta | Q8: Matutino | R8: Não | U8: Vandalismo na ferrovia com abertura de bicas em vagão graneleiro carregado fertilizante granular. | V8: Vandalismo com abertura de vagão graneleiro carregado com Fertilizante (Cloreto de Potassio). Lançamento de 10 tonelada de fertilizante granular sobre a linha férrea. | Z8: Ato criminoso caracterizado pela abertura de bicas em vagão graneleiro ferroviário carregado com fertilizante granular. | AA8: Solo dentro dos limites da área de domínio da via férrea. | AB8: Rumo Logistica S. A. | AC8: 02502844000166 | AD8: 1 | AE8: Equipes de atendimento de limpeza, contratadas pela Rumo, atuando no trecho afetado. | AH8: S | AI8: N | AJ8: S | AK8: Equipes de atendimento emergencial de limpeza, contratadas pela rumo, e de segurança patrimonial, atuando no trecho afetado para remoção do material, liberação da via e garantia da segurança dos trabalhadores. | AM8: Eloisa Caxias Coelho | AN8: Rumo Logistica S. A. | AO8: Auditora Ambiental | AP8: 41988207121 | AQ8: eloisa.coelho@rumolog.com | AX8: =IFERROR(FIND("Óbitos/feridos",consulta_completa__11[[#This Row],[13 - Ocorrências/Ambientes Atingidos]]),0) -> 0 | AY8: =IF(AX8=0,"","X") | AZ8: =IFERROR(FIND("População afetada/evacuada",consulta_completa__11[[#This Row],[13 - Ocorrências/Ambientes Atingidos]]),0) -> 0 | BA8: =IF(AZ8=0,"","X") | BB8: =IFERROR(FIND("Suspensão de abastecimento de água",consulta_completa__11[[#This Row],[13 - Ocorrências/Ambientes Atingidos]]),0) -> 0 | BC8: =IF(BB8=0,"","X") | BD8: =IFERROR(FIND("Rio/córrego",consulta_completa__11[[#This Row],[13 - Ocorrências/Ambientes Atingidos]]),0) -> 0 | BE8: =IF(BD8=0,"","X") | BF8: =IFERROR(FIND("Lago",consulta_completa__11[[#This Row],[13 - Ocorrências/Ambientes Atingidos]]),0) -> 0 | BG8: =IF(BF8=0,"","X") | BH8: =IFERROR(FIND("Mar",consulta_completa__11[[#This Row],[13 - Ocorrências/Ambientes Atingidos]]),0) -> 0 | BI8: =IF(BH8=0,"","X") | BJ8: =IFERROR(FIND("Praia",consulta_completa__11[[#This Row],[13 - Ocorrências/Ambientes Atingidos]]),0) -> 0 | BK8: =IF(BJ8=0,"","X") | BL8: =IFERROR(FIND("Solo",consulta_completa__11[[#This Row],[13 - Ocorrências/Ambientes Atingidos]]),0) -> 1 | BM8: =IF(BL8=0,"","X") -> X | BN8: =IFERROR(FIND("Águas subterrâneas",consulta_completa__11[[#This Row],[13 - Ocorrências/Ambientes Atingidos]]),0) -> 0 | BO8: =IF(BN8=0,"","X") | BP8: =IFERROR(FIND("Atmosfera",consulta_completa__11[[#This Row],[13 - Ocorrências/Ambientes Atingidos]]),0) -> 0 | BQ8: =IF(BP8=0,"","X") | BR8: =IFERROR(FIND("Flora",consulta_completa__11[[#This Row],[13 - Ocorrências/Ambientes Atingidos]]),0) -> 0 | BS8: =IF(BR8=0,"","X") | BT8: =IFERROR(FIND("Fauna",consulta_completa__11[[#This Row],[13 - Ocorrências/Ambientes Atingidos]]),0) -> 0 | BU8: =IF(BT8=0,"","X") | BV8: =IFERROR(FIND("UC federal",consulta_completa__11[[#This Row],[13 - Ocorrências/Ambientes Atingidos]]),0) -> 0 | BW8: =IF(BV8=0,"","X") | BX8: =IFERROR(FIND("UC estadual/municipal",consulta_completa__11[[#This Row],[13 - Ocorrências/Ambientes Atingidos]]),0) -> 0 | BY8: =IF(BX8=0,"","X") | BZ8: =IFERROR(FIND("Outro(s)",consulta_completa__11[[#This Row],[13 - Ocorrências/Ambientes Atingidos]]),0) -> 0 | CA8: =IF(BZ8=0,"","X") | CB8: =IFERROR(FIND("Sem dano",consulta_completa__11[[#This Row],[13 - Ocorrências/Ambientes Atingidos]]),0) -> 0 | CC8: =IF(CB8=0,"","X") | CD8: =IF(consulta_completa__11[[#This Row],[13 - Ocorrências/Ambientes Atingidos]]="","X","") | CE8: =IFERROR(FIND("IBAMA",consulta_completa__11[[#This Row],[14 - Inst. Atuando no Local]]),0) -> 0 | CF8: =IF(CE8=0,"","X") | CG8: =IFERROR(FIND("OEMA",consulta_completa__11[[#This Row],[14 - Inst. Atuando no Local]]),0) -> 0 | CH8: =IF(CG8=0,"","X") | CI8: =IFERROR(FIND("DEFESA CIVIL",consulta_completa__11[[#This Row],[14 - Inst. Atuando no Local]]),0) -> 0 | CJ8: =IF(CI8=0,"","X") | CK8: =IFERROR(FIND("CORPO DE BOMBEIROS",consulta_completa__11[[#This Row],[14 - Inst. Atuando no Local]]),0) -> 0 | CL8: =IF(CK8=0,"","X") | CM8: =IFERROR(FIND("POLÍCIA RODOVIÁRIA",consulta_completa__11[[#This Row],[14 - Inst. Atuando no Local]]),0) -> 0 | CN8: =IF(CM8=0,"","X") | CO8: =IFERROR(FIND("POLÍCIA MILITAR",consulta_completa__11[[#This Row],[14 - Inst. Atuando no Local]]),0) -> 0 | CP8: =IF(CO8=0,"","X") | CQ8: =IFERROR(FIND("POLÍCIA CIVIL",consulta_completa__11[[#This Row],[14 - Inst. Atuando no Local]]),0) -> 0 | CR8: =IF(CQ8=0,"","X") | CS8: =IFERROR(FIND("MARINHA DO BRASIL",consulta_completa__11[[#This Row],[14 - Inst. Atuando no Local]]),0) -> 0 | CT8: =IF(CS8=0,"","X") | CU8: =IFERROR(FIND("EMPRESA ESPECIALIZADA EM ATENDIMENTO",consulta_completa__11[[#This Row],[14 - Inst. Atuando no Local]]),0) -> 0 | CV8: =IF(CU8=0,"","X") | CW8: =IFERROR(FIND("IBAMA",consulta_completa__11[[#This Row],[14 - Inst. Atuando no Local]]),0) -> 0 | CX8: =IF(CW8=0,"","X") | CY8: =IF(consulta_completa__11[[#This Row],[14 - Inst. Atuando no Local]]="","X","") | CZ8: =IFERROR(FIND("OUTRA (S)",consulta_completa__11[[#This Row],[14 - Inst. Atuando no Local]]),0) -> 0 | DA8: =IF(CZ8=0,"","X") | DB8: =IF(AH$2="","",IF(AH$2="S","Sim",IF(AH$2="N","Não", IF(AH$2="I","Sem Informação")))) -> Sim | DC8: =IF(AI$2="","",IF(AI$2="S","Sim",IF(AI$2="N","Não", IF(AI$2="I","Sem Informação")))) -> Não | DD8: =IF(AJ$2="","",IF(AJ$2="S","Sim",IF(AJ$2="N","Não", IF(AJ$2="I","Sem Informação")))) -> Sim | DE8: =IF(AD8=1,"Federal",IF(AD8=2,"Estadual",IF(AD8=0,"Sem informação",""))) -> Federal
A9: 20251564830 | B9: 45661 | C9: null | D9: SP | E9: Plataforma | F9: Derramamento de líquidos | J9: Petroleo | K9: 0.034 | L9: M3 | M9: Mar | N9: Outra(s) | O9: Comunicado da empresa/responsável; Outra(s) fonte(s) | P9: Sábado | Q9: Madrugada | R9: Não | S9: Santos | T9: FPSO MARECHAL DUQUE DE CAXIAS (FPSO MDC), Campo de Mero, Bacia de Santos. | U9: Parada emergencial da planta de processo causada pela sensibilização de sensor de gás devido a perda de contenção primária de aproximadamente 0,5 m3 no permutador de placa óleo / óleo no módulo P50. Posteriormente, foi constatada por aeronave de asa fixa, feição oleosa com estimativa de 0,034 m3 conectada à instalação marítima. | V9: Feição oleosa com estimativa de 0,034 m3 conectada à instalação marítima | Z9: Falha no permutador de placas óleo/óleo. Em investigação. | AB9: Petrobras | AC9: 33000167000292 | AD9: 1 | AH9: S | AI9: S | AJ9: S | AK9: Parada imediata da unidade e blowdown da planta de processo. Após término da resposta inicial, foi realizada limpeza do óleo do deck atingidos pelo vazamento. Mobilização de embarcação Oil Recovery que realizou inspeção conforme modelagem e não constatou a feição. | AL9: Situação normalizada. Volume da feição oleosa estimada pela aeronave de asa fixa (Poseidon 2). | AM9: PETRLEO BRASILEIRO S/A - PETROBRAS | AQ9: giselletinoco@petrobras.com.br | AT9: FPSO MARECHAL DUQUE DE CAXIAS | AX9: =IFERROR(FIND("Óbitos/feridos",consulta_completa__11[[#This Row],[13 - Ocorrências/Ambientes Atingidos]]),0) -> 0 | AY9: =IF(AX9=0,"","X") | AZ9: =IFERROR(FIND("População afetada/evacuada",consulta_completa__11[[#This Row],[13 - Ocorrências/Ambientes Atingidos]]),0) -> 0 | BA9: =IF(AZ9=0,"","X") | BB9: =IFERROR(FIND("Suspensão de abastecimento de água",consulta_completa__11[[#This Row],[13 - Ocorrências/Ambientes Atingidos]]),0) -> 0 | BC9: =IF(BB9=0,"","X") | BD9: =IFERROR(FIND("Rio/córrego",consulta_completa__11[[#This Row],[13 - Ocorrências/Ambientes Atingidos]]),0) -> 0 | BE9: =IF(BD9=0,"","X") | BF9: =IFERROR(FIND("Lago",consulta_completa__11[[#This Row],[13 - Ocorrências/Ambientes Atingidos]]),0) -> 0 | BG9: =IF(BF9=0,"","X") | BH9: =IFERROR(FIND("Mar",consulta_completa__11[[#This Row],[13 - Ocorrências/Ambientes Atingidos]]),0) -> 1 | BI9: =IF(BH9=0,"","X") -> X | BJ9: =IFERROR(FIND("Praia",consulta_completa__11[[#This Row],[13 - Ocorrências/Ambientes Atingidos]]),0) -> 0 | BK9: =IF(BJ9=0,"","X") | BL9: =IFERROR(FIND("Solo",consulta_completa__11[[#This Row],[13 - Ocorrências/Ambientes Atingidos]]),0) -> 0 | BM9: =IF(BL9=0,"","X") | BN9: =IFERROR(FIND("Águas subterrâneas",consulta_completa__11[[#This Row],[13 - Ocorrências/Ambientes Atingidos]]),0) -> 0 | BO9: =IF(BN9=0,"","X") | BP9: =IFERROR(FIND("Atmosfera",consulta_completa__11[[#This Row],[13 - Ocorrências/Ambientes Atingidos]]),0) -> 0 | BQ9: =IF(BP9=0,"","X") | BR9: =IFERROR(FIND("Flora",consulta_completa__11[[#This Row],[13 - Ocorrências/Ambientes Atingidos]]),0) -> 0 | BS9: =IF(BR9=0,"","X") | BT9: =IFERROR(FIND("Fauna",consulta_completa__11[[#This Row],[13 - Ocorrências/Ambientes Atingidos]]),0) -> 0 | BU9: =IF(BT9=0,"","X") | BV9: =IFERROR(FIND("UC federal",consulta_completa__11[[#This Row],[13 - Ocorrências/Ambientes Atingidos]]),0) -> 0 | BW9: =IF(BV9=0,"","X") | BX9: =IFERROR(FIND("UC estadual/municipal",consulta_completa__11[[#This Row],[13 - Ocorrências/Ambientes Atingidos]]),0) -> 0 | BY9: =IF(BX9=0,"","X") | BZ9: =IFERROR(FIND("Outro(s)",consulta_completa__11[[#This Row],[13 - Ocorrências/Ambientes Atingidos]]),0) -> 0 | CA9: =IF(BZ9=0,"","X") | CB9: =IFERROR(FIND("Sem dano",consulta_completa__11[[#This Row],[13 - Ocorrências/Ambientes Atingidos]]),0) -> 0 | CC9: =IF(CB9=0,"","X") | CD9: =IF(consulta_completa__11[[#This Row],[13 - Ocorrências/Ambientes Atingidos]]="","X","") | CE9: =IFERROR(FIND("IBAMA",consulta_completa__11[[#This Row],[14 - Inst. Atuando no Local]]),0) -> 0 | CF9: =IF(CE9=0,"","X") | CG9: =IFERROR(FIND("OEMA",consulta_completa__11[[#This Row],[14 - Inst. Atuando no Local]]),0) -> 0 | CH9: =IF(CG9=0,"","X") | CI9: =IFERROR(FIND("DEFESA CIVIL",consulta_completa__11[[#This Row],[14 - Inst. Atuando no Local]]),0) -> 0 | CJ9: =IF(CI9=0,"","X") | CK9: =IFERROR(FIND("CORPO DE BOMBEIROS",consulta_completa__11[[#This Row],[14 - Inst. Atuando no Local]]),0) -> 0 | CL9: =IF(CK9=0,"","X") | CM9: =IFERROR(FIND("POLÍCIA RODOVIÁRIA",consulta_completa__11[[#This Row],[14 - Inst. Atuando no Local]]),0) -> 0 | CN9: =IF(CM9=0,"","X") | CO9: =IFERROR(FIND("POLÍCIA MILITAR",consulta_completa__11[[#This Row],[14 - Inst. Atuando no Local]]),0) -> 0 | CP9: =IF(CO9=0,"","X") | CQ9: =IFERROR(FIND("POLÍCIA CIVIL",consulta_completa__11[[#This Row],[14 - Inst. Atuando no Local]]),0) -> 0 | CR9: =IF(CQ9=0,"","X") | CS9: =IFERROR(FIND("MARINHA DO BRASIL",consulta_completa__11[[#This Row],[14 - Inst. Atuando no Local]]),0) -> 0 | CT9: =IF(CS9=0,"","X") | CU9: =IFERROR(FIND("EMPRESA ESPECIALIZADA EM ATENDIMENTO",consulta_completa__11[[#This Row],[14 - Inst. Atuando no Local]]),0) -> 0 | CV9: =IF(CU9=0,"","X") | CW9: =IFERROR(FIND("IBAMA",consulta_completa__11[[#This Row],[14 - Inst. Atuando no Local]]),0) -> 0 | CX9: =IF(CW9=0,"","X") | CY9: =IF(consulta_completa__11[[#This Row],[14 - Inst. Atuando no Local]]="","X","") | CZ9: =IFERROR(FIND("OUTRA (S)",consulta_completa__11[[#This Row],[14 - Inst. Atuando no Local]]),0) -> 0 | DA9: =IF(CZ9=0,"","X") | DB9: =IF(AH$2="","",IF(AH$2="S","Sim",IF(AH$2="N","Não", IF(AH$2="I","Sem Informação")))) -> Sim | DC9: =IF(AI$2="","",IF(AI$2="S","Sim",IF(AI$2="N","Não", IF(AI$2="I","Sem Informação")))) -> Não | DD9: =IF(AJ$2="","",IF(AJ$2="S","Sim",IF(AJ$2="N","Não", IF(AJ$2="I","Sem Informação")))) -> Sim | DE9: =IF(AD9=1,"Federal",IF(AD9=2,"Estadual",IF(AD9=0,"Sem informação",""))) -> Federal
A10: 20251657612 | B10: 45661 | C10: Macaé | D10: RJ | E10: Plataforma | F10: Derramamento de líquidos | M10: Mar | O10: Comunicado da empresa/responsável | P10: Sábado | Q10: Vespertino | R10: Não | S10: Campos | T10: Polo Pargo - Bacia de Campos | V10: No dia 04 de janeiro de 2025, às 14h30, foi detectada uma feição oleosa na face oeste de PPG1-B, originada de um pequeno vazamento de diesel proveniente de uma linha de 2%u2019%u2019, responsável pela transferência do combustível do tanque para a centrífuga. A maior parte do vazamento, aproximadamente 1 litro, ficou contida na plataforma, mas estima-se que cerca de 200 ml de diesel tenham alcançado o mar. A linha foi imediatamente isolada e reparada por uma empresa especializada, utilizando material compósito. A feição de coloração prateada/iridescente, com dimensões de 5x5m, foi localizada e rapidamente dispersada. | X10: TRUE | Z10: Em investigação | AB10: Perenco Petróleo e Gás do Brasil Ltda. | AC10: 09309027000135 | AD10: 1 | AH10: S | AI10: N | AJ10: S | AK10: A linha de 2%u2019%u2019 foi isolada e o vazamento foi contido. Um reparo com aplicação de compósito foi efetuado. O reparo realizado foi certificado pela empresa especializada que realizou o serviço. | AL10: Um reparo com aplicação de compósito foi efetuado. O reparo realizado foi certificado pela empresa especializada que realizou o serviço. | AM10: PERENCO PETRLEO E GS DO BRASIL LTDA | AN10: PERENCO PETRÓLEO E GÁS DO BRASIL LTDA. | AO10: GERENTE DE QHSE | AP10: 21998863038 | AQ10: mgonin@br.perenco.com | AT10: Pargo-PPG-1B | AU10: Óleo diesel | AV10: 12000000 | AW10: Paralisada | AX10: =IFERROR(FIND("Óbitos/feridos",consulta_completa__11[[#This Row],[13 - Ocorrências/Ambientes Atingidos]]),0) -> 0 | AY10: =IF(AX10=0,"","X") | AZ10: =IFERROR(FIND("População afetada/evacuada",consulta_completa__11[[#This Row],[13 - Ocorrências/Ambientes Atingidos]]),0) -> 0 | BA10: =IF(AZ10=0,"","X") | BB10: =IFERROR(FIND("Suspensão de abastecimento de água",consulta_completa__11[[#This Row],[13 - Ocorrências/Ambientes Atingidos]]),0) -> 0 | BC10: =IF(BB10=0,"","X") | BD10: =IFERROR(FIND("Rio/córrego",consulta_completa__11[[#This Row],[13 - Ocorrências/Ambientes Atingidos]]),0) -> 0 | BE10: =IF(BD10=0,"","X") | BF10: =IFERROR(FIND("Lago",consulta_completa__11[[#This Row],[13 - Ocorrências/Ambientes Atingidos]]),0) -> 0 | BG10: =IF(BF10=0,"","X") | BH10: =IFERROR(FIND("Mar",consulta_completa__11[[#This Row],[13 - Ocorrências/Ambientes Atingidos]]),0) -> 1 | BI10: =IF(BH10=0,"","X") -> X | BJ10: =IFERROR(FIND("Praia",consulta_completa__11[[#This Row],[13 - Ocorrências/Ambientes Atingidos]]),0) -> 0 | BK10: =IF(BJ10=0,"","X") | BL10: =IFERROR(FIND("Solo",consulta_completa__11[[#This Row],[13 - Ocorrências/Ambientes Atingidos]]),0) -> 0 | BM10: =IF(BL10=0,"","X") | BN10: =IFERROR(FIND("Águas subterrâneas",consulta_completa__11[[#This Row],[13 - Ocorrências/Ambientes Atingidos]]),0) -> 0 | BO10: =IF(BN10=0,"","X") | BP10: =IFERROR(FIND("Atmosfera",consulta_completa__11[[#This Row],[13 - Ocorrências/Ambientes Atingidos]]),0) -> 0 | BQ10: =IF(BP10=0,"","X") | BR10: =IFERROR(FIND("Flora",consulta_completa__11[[#This Row],[13 - Ocorrências/Ambientes Atingidos]]),0) -> 0 | BS10: =IF(BR10=0,"","X") | BT10: =IFERROR(FIND("Fauna",consulta_completa__11[[#This Row],[13 - Ocorrências/Ambientes Atingidos]]),0) -> 0 | BU10: =IF(BT10=0,"","X") | BV10: =IFERROR(FIND("UC federal",consulta_completa__11[[#This Row],[13 - Ocorrências/Ambientes Atingidos]]),0) -> 0 | BW10: =IF(BV10=0,"","X") | BX10: =IFERROR(FIND("UC estadual/municipal",consulta_completa__11[[#This Row],[13 - Ocorrências/Ambientes Atingidos]]),0) -> 0 | BY10: =IF(BX10=0,"","X") | BZ10: =IFERROR(FIND("Outro(s)",consulta_completa__11[[#This Row],[13 - Ocorrências/Ambientes Atingidos]]),0) -> 0 | CA10: =IF(BZ10=0,"","X") | CB10: =IFERROR(FIND("Sem dano",consulta_completa__11[[#This Row],[13 - Ocorrências/Ambientes Atingidos]]),0) -> 0 | CC10: =IF(CB10=0,"","X") | CD10: =IF(consulta_completa__11[[#This Row],[13 - Ocorrências/Ambientes Atingidos]]="","X","") | CE10: =IFERROR(FIND("IBAMA",consulta_completa__11[[#This Row],[14 - Inst. Atuando no Local]]),0) -> 0 | CF10: =IF(CE10=0,"","X") | CG10: =IFERROR(FIND("OEMA",consulta_completa__11[[#This Row],[14 - Inst. Atuando no Local]]),0) -> 0 | CH10: =IF(CG10=0,"","X") | CI10: =IFERROR(FIND("DEFESA CIVIL",consulta_completa__11[[#This Row],[14 - Inst. Atuando no Local]]),0) -> 0 | CJ10: =IF(CI10=0,"","X") | CK10: =IFERROR(FIND("CORPO DE BOMBEIROS",consulta_completa__11[[#This Row],[14 - Inst. Atuando no Local]]),0) -> 0 | CL10: =IF(CK10=0,"","X") | CM10: =IFERROR(FIND("POLÍCIA RODOVIÁRIA",consulta_completa__11[[#This Row],[14 - Inst. Atuando no Local]]),0) -> 0 | CN10: =IF(CM10=0,"","X") | CO10: =IFERROR(FIND("POLÍCIA MILITAR",consulta_completa__11[[#This Row],[14 - Inst. Atuando no Local]]),0) -> 0 | CP10: =IF(CO10=0,"","X") | CQ10: =IFERROR(FIND("POLÍCIA CIVIL",consulta_completa__11[[#This Row],[14 - Inst. Atuando no Local]]),0) -> 0 | CR10: =IF(CQ10=0,"","X") | CS10: =IFERROR(FIND("MARINHA DO BRASIL",consulta_completa__11[[#This Row],[14 - Inst. Atuando no Local]]),0) -> 0 | CT10: =IF(CS10=0,"","X") | CU10: =IFERROR(FIND("EMPRESA ESPECIALIZADA EM ATENDIMENTO",consulta_completa__11[[#This Row],[14 - Inst. Atuando no Local]]),0) -> 0 | CV10: =IF(CU10=0,"","X") | CW10: =IFERROR(FIND("IBAMA",consulta_completa__11[[#This Row],[14 - Inst. Atuando no Local]]),0) -> 0 | CX10: =IF(CW10=0,"","X") | CY10: =IF(consulta_completa__11[[#This Row],[14 - Inst. Atuando no Local]]="","X","") -> X | CZ10: =IFERROR(FIND("OUTRA (S)",consulta_completa__11[[#This Row],[14 - Inst. Atuando no Local]]),0) -> 0 | DA10: =IF(CZ10=0,"","X") | DB10: =IF(AH$2="","",IF(AH$2="S","Sim",IF(AH$2="N","Não", IF(AH$2="I","Sem Informação")))) -> Sim | DC10: =IF(AI$2="","",IF(AI$2="S","Sim",IF(AI$2="N","Não", IF(AI$2="I","Sem Informação")))) -> Não | DD10: =IF(AJ$2="","",IF(AJ$2="S","Sim",IF(AJ$2="N","Não", IF(AJ$2="I","Sem Informação")))) -> Sim | DE10: =IF(AD10=1,"Federal",IF(AD10=2,"Estadual",IF(AD10=0,"Sem informação",""))) -> Federal
